Workbook

Sheet Mis fechas
B2: Calendario tributario 2026 por NIT
B3: Tus fechas DIAN de renta, IVA, retención y Régimen Simple en un solo lugar
B4: WhatsApp 300 507 4934 · solucontfisc@gmail.com · recursos.solucioncontableyfiscal.com
B8: Tus datos | C8: Escribe solo en las celdas amarillas; el resto se calcula solo.
B10: 1. TU NIT
B11: Dos últimos dígitos del NIT (sin dígito de verificación) | C11: 34 | D11: Ejemplo: NIT 900.123.434-5 → 34
B12: Último dígito | C12: =MOD(C11,10)
B14: 2. RESUMEN
B15: Renta personas naturales (año gravable 2025) | C15: =VLOOKUP(MOD(C11,100),'Datos DIAN 2026'!$P$2:$Q$101,2,FALSE)
B16: Hoy | C16: =TODAY()
B17: Tu próximo vencimiento | C17: =IFERROR(1/(1/_xlfn.MINIFS($D$21:$D$54,$D$21:$D$54,">="&TODAY())),"Sin pendientes") | D17: =IFERROR(INDEX($B$21:$B$54,MATCH(C17,$D$21:$D$54,0))&" · "&INDEX($C$21:$C$54,MATCH(C17,$D$21:$D$54,0)),"")
B19: 3. TUS FECHAS 2026
B20: Obligación | C20: Período | D20: Fecha límite | E20: Días que faltan | F20: Estado
B21: ='Datos DIAN 2026'!A2 | C21: ='Datos DIAN 2026'!B2 | D21: =INDEX('Datos DIAN 2026'!$D$2:$M$2,MATCH($C$12,'Datos DIAN 2026'!$D$1:$M$1,0)) | E21: =IF(D21<TODAY(),"",D21-TODAY()) | F21: =IF(D21<TODAY(),"Vencido",IF(D21-TODAY()<=15,"Vence pronto","Pendiente"))
B22: ='Datos DIAN 2026'!A3 | C22: ='Datos DIAN 2026'!B3 | D22: =INDEX('Datos DIAN 2026'!$D$3:$M$3,MATCH($C$12,'Datos DIAN 2026'!$D$1:$M$1,0)) | E22: =IF(D22<TODAY(),"",D22-TODAY()) | F22: =IF(D22<TODAY(),"Vencido",IF(D22-TODAY()<=15,"Vence pronto","Pendiente"))
B23: ='Datos DIAN 2026'!A4 | C23: ='Datos DIAN 2026'!B4 | D23: =INDEX('Datos DIAN 2026'!$D$4:$M$4,MATCH($C$12,'Datos DIAN 2026'!$D$1:$M$1,0)) | E23: =IF(D23<TODAY(),"",D23-TODAY()) | F23: =IF(D23<TODAY(),"Vencido",IF(D23-TODAY()<=15,"Vence pronto","Pendiente"))
B24: ='Datos DIAN 2026'!A5 | C24: ='Datos DIAN 2026'!B5 | D24: =INDEX('Datos DIAN 2026'!$D$5:$M$5,MATCH($C$12,'Datos DIAN 2026'!$D$1:$M$1,0)) | E24: =IF(D24<TODAY(),"",D24-TODAY()) | F24: =IF(D24<TODAY(),"Vencido",IF(D24-TODAY()<=15,"Vence pronto","Pendiente"))
B25: ='Datos DIAN 2026'!A6 | C25: ='Datos DIAN 2026'!B6 | D25: =INDEX('Datos DIAN 2026'!$D$6:$M$6,MATCH($C$12,'Datos DIAN 2026'!$D$1:$M$1,0)) | E25: =IF(D25<TODAY(),"",D25-TODAY()) | F25: =IF(D25<TODAY(),"Vencido",IF(D25-TODAY()<=15,"Vence pronto","Pendiente"))
B26: ='Datos DIAN 2026'!A7 | C26: ='Datos DIAN 2026'!B7 | D26: =INDEX('Datos DIAN 2026'!$D$7:$M$7,MATCH($C$12,'Datos DIAN 2026'!$D$1:$M$1,0)) | E26: =IF(D26<TODAY(),"",D26-TODAY()) | F26: =IF(D26<TODAY(),"Vencido",IF(D26-TODAY()<=15,"Vence pronto","Pendiente"))
B27: ='Datos DIAN 2026'!A8 | C27: ='Datos DIAN 2026'!B8 | D27: =INDEX('Datos DIAN 2026'!$D$8:$M$8,MATCH($C$12,'Datos DIAN 2026'!$D$1:$M$1,0)) | E27: =IF(D27<TODAY(),"",D27-TODAY()) | F27: =IF(D27<TODAY(),"Vencido",IF(D27-TODAY()<=15,"Vence pronto","Pendiente"))
B28: ='Datos DIAN 2026'!A9 | C28: ='Datos DIAN 2026'!B9 | D28: =INDEX('Datos DIAN 2026'!$D$9:$M$9,MATCH($C$12,'Datos DIAN 2026'!$D$1:$M$1,0)) | E28: =IF(D28<TODAY(),"",D28-TODAY()) | F28: =IF(D28<TODAY(),"Vencido",IF(D28-TODAY()<=15,"Vence pronto","Pendiente"))
B29: ='Datos DIAN 2026'!A10 | C29: ='Datos DIAN 2026'!B10 | D29: =INDEX('Datos DIAN 2026'!$D$10:$M$10,MATCH($C$12,'Datos DIAN 2026'!$D$1:$M$1,0)) | E29: =IF(D29<TODAY(),"",D29-TODAY()) | F29: =IF(D29<TODAY(),"Vencido",IF(D29-TODAY()<=15,"Vence pronto","Pendiente"))
B30: ='Datos DIAN 2026'!A11 | C30: ='Datos DIAN 2026'!B11 | D30: =INDEX('Datos DIAN 2026'!$D$11:$M$11,MATCH($C$12,'Datos DIAN 2026'!$D$1:$M$1,0)) | E30: =IF(D30<TODAY(),"",D30-TODAY()) | F30: =IF(D30<TODAY(),"Vencido",IF(D30-TODAY()<=15,"Vence pronto","Pendiente"))
B31: ='Datos DIAN 2026'!A12 | C31: ='Datos DIAN 2026'!B12 | D31: =INDEX('Datos DIAN 2026'!$D$12:$M$12,MATCH($C$12,'Datos DIAN 2026'!$D$1:$M$1,0)) | E31: =IF(D31<TODAY(),"",D31-TODAY()) | F31: =IF(D31<TODAY(),"Vencido",IF(D31-TODAY()<=15,"Vence pronto","Pendiente"))
B32: ='Datos DIAN 2026'!A13 | C32: ='Datos DIAN 2026'!B13 | D32: =INDEX('Datos DIAN 2026'!$D$13:$M$13,MATCH($C$12,'Datos DIAN 2026'!$D$1:$M$1,0)) | E32: =IF(D32<TODAY(),"",D32-TODAY()) | F32: =IF(D32<TODAY(),"Vencido",IF(D32-TODAY()<=15,"Vence pronto","Pendiente"))
B33: ='Datos DIAN 2026'!A14 | C33: ='Datos DIAN 2026'!B14 | D33: =INDEX('Datos DIAN 2026'!$D$14:$M$14,MATCH($C$12,'Datos DIAN 2026'!$D$1:$M$1,0)) | E33: =IF(D33<TODAY(),"",D33-TODAY()) | F33: =IF(D33<TODAY(),"Vencido",IF(D33-TODAY()<=15,"Vence pronto","Pendiente"))
B34: ='Datos DIAN 2026'!A15 | C34: ='Datos DIAN 2026'!B15 | D34: =INDEX('Datos DIAN 2026'!$D$15:$M$15,MATCH($C$12,'Datos DIAN 2026'!$D$1:$M$1,0)) | E34: =IF(D34<TODAY(),"",D34-TODAY()) | F34: =IF(D34<TODAY(),"Vencido",IF(D34-TODAY()<=15,"Vence pronto","Pendiente"))
B35: ='Datos DIAN 2026'!A16 | C35: ='Datos DIAN 2026'!B16 | D35: =INDEX('Datos DIAN 2026'!$D$16:$M$16,MATCH($C$12,'Datos DIAN 2026'!$D$1:$M$1,0)) | E35: =IF(D35<TODAY(),"",D35-TODAY()) | F35: =IF(D35<TODAY(),"Vencido",IF(D35-TODAY()<=15,"Vence pronto","Pendiente"))
B36: ='Datos DIAN 2026'!A17 | C36: ='Datos DIAN 2026'!B17 | D36: =INDEX('Datos DIAN 2026'!$D$17:$M$17,MATCH($C$12,'Datos DIAN 2026'!$D$1:$M$1,0)) | E36: =IF(D36<TODAY(),"",D36-TODAY()) | F36: =IF(D36<TODAY(),"Vencido",IF(D36-TODAY()<=15,"Vence pronto","Pendiente"))
B37: ='Datos DIAN 2026'!A18 | C37: ='Datos DIAN 2026'!B18 | D37: =INDEX('Datos DIAN 2026'!$D$18:$M$18,MATCH($C$12,'Datos DIAN 2026'!$D$1:$M$1,0)) | E37: =IF(D37<TODAY(),"",D37-TODAY()) | F37: =IF(D37<TODAY(),"Vencido",IF(D37-TODAY()<=15,"Vence pronto","Pendiente"))
B38: ='Datos DIAN 2026'!A19 | C38: ='Datos DIAN 2026'!B19 | D38: =INDEX('Datos DIAN 2026'!$D$19:$M$19,MATCH($C$12,'Datos DIAN 2026'!$D$1:$M$1,0)) | E38: =IF(D38<TODAY(),"",D38-TODAY()) | F38: =IF(D38<TODAY(),"Vencido",IF(D38-TODAY()<=15,"Vence pronto","Pendiente"))
B39: ='Datos DIAN 2026'!A20 | C39: ='Datos DIAN 2026'!B20 | D39: =INDEX('Datos DIAN 2026'!$D$20:$M$20,MATCH($C$12,'Datos DIAN 2026'!$D$1:$M$1,0)) | E39: =IF(D39<TODAY(),"",D39-TODAY()) | F39: =IF(D39<TODAY(),"Vencido",IF(D39-TODAY()<=15,"Vence pronto","Pendiente"))
B40: ='Datos DIAN 2026'!A21 | C40: ='Datos DIAN 2026'!B21 | D40: =INDEX('Datos DIAN 2026'!$D$21:$M$21,MATCH($C$12,'Datos DIAN 2026'!$D$1:$M$1,0)) | E40: =IF(D40<TODAY(),"",D40-TODAY()) | F40: =IF(D40<TODAY(),"Vencido",IF(D40-TODAY()<=15,"Vence pronto","Pendiente"))
B41: ='Datos DIAN 2026'!A22 | C41: ='Datos DIAN 2026'!B22 | D41: =INDEX('Datos DIAN 2026'!$D$22:$M$22,MATCH($C$12,'Datos DIAN 2026'!$D$1:$M$1,0)) | E41: =IF(D41<TODAY(),"",D41-TODAY()) | F41: =IF(D41<TODAY(),"Vencido",IF(D41-TODAY()<=15,"Vence pronto","Pendiente"))
B42: ='Datos DIAN 2026'!A23 | C42: ='Datos DIAN 2026'!B23 | D42: =INDEX('Datos DIAN 2026'!$D$23:$M$23,MATCH($C$12,'Datos DIAN 2026'!$D$1:$M$1,0)) | E42: =IF(D42<TODAY(),"",D42-TODAY()) | F42: =IF(D42<TODAY(),"Vencido",IF(D42-TODAY()<=15,"Vence pronto","Pendiente"))
B43: ='Datos DIAN 2026'!A24 | C43: ='Datos DIAN 2026'!B24 | D43: =INDEX('Datos DIAN 2026'!$D$24:$M$24,MATCH($C$12,'Datos DIAN 2026'!$D$1:$M$1,0)) | E43: =IF(D43<TODAY(),"",D43-TODAY()) | F43: =IF(D43<TODAY(),"Vencido",IF(D43-TODAY()<=15,"Vence pronto","Pendiente"))
B44: ='Datos DIAN 2026'!A25 | C44: ='Datos DIAN 2026'!B25 | D44: =INDEX('Datos DIAN 2026'!$D$25:$M$25,MATCH($C$12,'Datos DIAN 2026'!$D$1:$M$1,0)) | E44: =IF(D44<TODAY(),"",D44-TODAY()) | F44: =IF(D44<TODAY(),"Vencido",IF(D44-TODAY()<=15,"Vence pronto","Pendiente"))
B45: ='Datos DIAN 2026'!A26 | C45: ='Datos DIAN 2026'!B26 | D45: =INDEX('Datos DIAN 2026'!$D$26:$M$26,MATCH($C$12,'Datos DIAN 2026'!$D$1:$M$1,0)) | E45: =IF(D45<TODAY(),"",D45-TODAY()) | F45: =IF(D45<TODAY(),"Vencido",IF(D45-TODAY()<=15,"Vence pronto","Pendiente"))
B46: ='Datos DIAN 2026'!A27 | C46: ='Datos DIAN 2026'!B27 | D46: =INDEX('Datos DIAN 2026'!$D$27:$M$27,MATCH($C$12,'Datos DIAN 2026'!$D$1:$M$1,0)) | E46: =IF(D46<TODAY(),"",D46-TODAY()) | F46: =IF(D46<TODAY(),"Vencido",IF(D46-TODAY()<=15,"Vence pronto","Pendiente"))
B47: ='Datos DIAN 2026'!A28 | C47: ='Datos DIAN 2026'!B28 | D47: =INDEX('Datos DIAN 2026'!$D$28:$M$28,MATCH($C$12,'Datos DIAN 2026'!$D$1:$M$1,0)) | E47: =IF(D47<TODAY(),"",D47-TODAY()) | F47: =IF(D47<TODAY(),"Vencido",IF(D47-TODAY()<=15,"Vence pronto","Pendiente"))
...

Sheet Datos DIAN 2026
A1: Obligación | B1: Período | C1: Mes de vencimiento | D1: 1 | E1: 2 | F1: 3 | G1: 4 | H1: 5 | I1: 6 | J1: 7 | K1: 8 | L1: 9 | M1: 0 | P1: Dos últimos dígitos | Q1: Renta personas naturales
A2: Renta grandes contribuyentes | B2: Pago 1.ª cuota | C2: 2026-02 | D2: 46063 | E2: 46064 | F2: 46065 | G2: 46066 | H2: 46069 | I2: 46070 | J2: 46071 | K2: 46072 | L2: 46073 | M2: 46076 | P2: 0 | Q2: 46321
A3: Renta grandes contribuyentes | B3: Declaración y pago 2.ª cuota | C3: 2026-04 | D3: 46125 | E3: 46126 | F3: 46127 | G3: 46128 | H3: 46132 | I3: 46133 | J3: 46134 | K3: 46135 | L3: 46136 | M3: 46139 | P3: 1 | Q3: 46246
A4: Renta grandes contribuyentes | B4: Pago 3.ª cuota | C4: 2026-06 | D4: 46183 | E4: 46184 | F4: 46185 | G4: 46189 | H4: 46190 | I4: 46191 | J4: 46192 | K4: 46195 | L4: 46196 | M4: 46197 | P4: 2 | Q4: 46246
A5: Renta personas jurídicas | B5: Declaración y pago 1.ª cuota | C5: 2026-05 | D5: 46154 | E5: 46155 | F5: 46156 | G5: 46157 | H5: 46161 | I5: 46162 | J5: 46163 | K5: 46164 | L5: 46167 | M5: 46168 | P5: 3 | Q5: 46247
A6: Renta personas jurídicas | B6: Pago 2.ª cuota | C6: 2026-07 | D6: 46212 | E6: 46213 | F6: 46217 | G6: 46218 | H6: 46219 | I6: 46220 | J6: 46224 | K6: 46225 | L6: 46226 | M6: 46227 | P6: 4 | Q6: 46247
A7: IVA bimestral | B7: enero–febrero | C7: 2026-03 | D7: 46091 | E7: 46092 | F7: 46093 | G7: 46094 | H7: 46097 | I7: 46098 | J7: 46099 | K7: 46100 | L7: 46101 | M7: 46105 | P7: 5 | Q7: 46248
A8: IVA bimestral | B8: marzo–abril | C8: 2026-05 | D8: 46154 | E8: 46155 | F8: 46156 | G8: 46157 | H8: 46161 | I8: 46162 | J8: 46163 | K8: 46164 | L8: 46167 | M8: 46168 | P8: 6 | Q8: 46248
A9: IVA bimestral | B9: mayo–junio | C9: 2026-07 | D9: 46212 | E9: 46213 | F9: 46217 | G9: 46218 | H9: 46219 | I9: 46220 | J9: 46224 | K9: 46225 | L9: 46226 | M9: 46227 | P9: 7 | Q9: 46252
A10: IVA bimestral | B10: julio–agosto | C10: 2026-09 | D10: 46274 | E10: 46275 | F10: 46276 | G10: 46279 | H10: 46280 | I10: 46281 | J10: 46282 | K10: 46283 | L10: 46286 | M10: 46287 | P10: 8 | Q10: 46252
A11: IVA bimestral | B11: septiembre–octubre | C11: 2026-11 | D11: 46337 | E11: 46338 | F11: 46339 | G11: 46343 | H11: 46344 | I11: 46345 | J11: 46346 | K11: 46349 | L11: 46350 | M11: 46351 | P11: 9 | Q11: 46253
A12: IVA bimestral | B12: noviembre–diciembre | C12: 2027-01 | D12: 46400 | E12: 46401 | F12: 46402 | G12: 46405 | H12: 46406 | I12: 46407 | J12: 46408 | K12: 46409 | L12: 46412 | M12: 46413 | P12: 10 | Q12: 46253
A13: IVA cuatrimestral | B13: enero–abril | C13: 2026-05 | D13: 46154 | E13: 46155 | F13: 46156 | G13: 46157 | H13: 46161 | I13: 46162 | J13: 46163 | K13: 46164 | L13: 46167 | M13: 46168 | P13: 11 | Q13: 46254
... A35: Régimen Simple · IVA anual consolidado | B35: año 2025 | C35: 2026-02 | D35: 46069 | E35: 46069 | F35: 46070 | G35: 46070 | H35: 46071 | I35: 46071 | J35: 46072 | K35: 46072 | L35: 46073 | M35: 46073 | P35: 33 | Q35: 46269
P36: 34 | Q36: 46269
P37: 35 | Q37: 46272
P38: 36 | Q38: 46272
P39: 37 | Q39: 46273
P40: 38 | Q40: 46273
P41: 39 | Q41: 46274
P42: 40 | Q42: 46274
P43: 41 | Q43: 46275
P44: 42 | Q44: 46275
P45: 43 | Q45: 46276
P46: 44 | Q46: 46276
P47: 45 | Q47: 46279
... P101: 99 | Q101: 46321
